Workbook

Sheet Concepts
C1: Essential Excel Functions & Formulas
D5: Business Question: | F5: Function(s) you'll learn: | G5: Challenge for you…
C6: 1 | D6: Total Salary and headcount by department | F6: SUMIFS, COUNTIFS | G6: Permanent headcount
C7: 2 | D7: All employees with more than $100k salary | F7: FILTER
C8: 3 | D8: All female employees with more than $100k salary | F8: FILTER, * | G8: who joined in 2020 or after…
C9: 4 | D9: Lowest, highest and top 5 salary values | F9: MIN, MAX, LARGE, SORT + TAKE
C10: 5 | D10: List of all departments | F10: UNIQUE, COUNTA, # | G10: All depts in one cell, comma seperated
C11: 6 | D11: Employee details lookup | F11: VLOOKUP, INDEX + MATCH
C12: 7 | D12: Employee details lookup | F12: XLOOKUP, IFERROR | G12: Find all employees with 120,000 salary
C13: 8 | D13: Complex formula: Highest salary person | F13: XLOOKUP + MAX
C14: 9 | D14: Complex formula: All employees joined in March | F14: FILTER + MONTH | G14: Female employees with Monday start
C15: 10 | D15: Complex formula: Department report of headcounts, salaries and % diff from overall average | F15: UNIQUE, SUMIFS, COUNTIFS, #, CONDITIONAL FORMATTING | G15: Calculate Median Salary and Female Ratio

Sheet Data
C1: Essential Excel Functions & Formulas
C7: Emp ID | D7: First Name | E7: Last Name | F7: Gender | G7: Department | H7: Salary | I7: Salary Bucket | J7: Start Date | K7: FTE | L7: Employee type | M7: Work location | N7: Tenure | O7: Work Type
C8: PR00147 | D8: Minerva | E8: Ricardot | F8: Male | G8: Engineering | H8: 120000 | I8: Above 100k | J8: 43416 | K8: 1 | L8: Permanent | M8: Remote | N8: 5.6109589 | O8: Full time
C9: SQ04612 | D9: Mick | E9: Spraberry | F9: Female | G9: Services | H9: 120000 | I9: Above 100k | J9: 43902 | K9: 0.9 | L9: Permanent | M9: Remote | N9: 4.2794521 | O9: Part time
C10: PR03886 | D10: Edd | E10: MacKnockiter | F10: Male | G10: Accounting | H10: 119022.49 | I10: Above 100k | J10: 44431 | K10: 1 | L10: Permanent | M10: Auckland, New Zealand | N10: 2.830137 | O10: Full time
C11: SQ00144 | D11: Collen | E11: Dunbleton | F11: Male | G11: Engineering | H11: 118976.16 | I11: Above 100k | J11: 44120 | K11: 1 | L11: Permanent | M11: Wellington, New Zealand | N11: 3.6821918 | O11: Full time
C12: SQ02174 | D12: Sidoney | E12: Yitzhok | F12: Female | G12: Engineering | H12: 118442.54 | I12: Above 100k | J12: 44193 | K12: 1 | L12: Permanent | M12: Auckland, New Zealand | N12: 3.4821918 | O12: Full time
C13: VT04093 | D13: Prasanna | E13: Lakshmi | F13: Female | G13: Training | H13: 116767.63 | I13: Above 100k | J13: 43949 | K13: 0.4 | L13: Temporary | M13: Chennai, India | N13: 4.1506849 | O13: Part time
C14: VT04093 | D14: Baruna | E14: Ogale | F14: Female | G14: Training | H14: 116767.63 | I14: Above 100k | J14: 43949 | K14: 0.4 | L14: Temporary | M14: Chennai, India | N14: 4.1506849 | O14: Part time
C15: PR02010 | D15: Prerana | E15: Nishita | F15: Male | G15: Product Management | H15: 115191.38 | I15: Above 100k | J15: 44004 | K15: 1 | L15: Permanent | M15: Hyderabad, India | N15: 4 | O15: Full time
C16: SQ02624 | D16: Gwenneth | E16: Fealey | F16: Female | G16: Engineering | H16: 114772.32 | I16: Above 100k | J16: 44251 | K16: 1 | L16: Permanent | M16: Columbus, USA | N16: 3.3232877 | O16: Full time
C17: VT02801 | D17: Shellysheldon | E17: Mahady | F17: Male | G17: Training | H17: 114691.03 | I17: Above 100k | J17: 44039 | K17: 1 | L17: Temporary | M17: Wellington, New Zealand | N17: 3.9041096 | O17: Full time
C18: VT02491 | D18: Alexis | E18: Gotfrey | F18: Male | G18: Engineering | H18: 114465.93 | I18: Above 100k | J18: 43291 | K18: 1 | L18: Temporary | M18: Wellington, New Zealand | N18: 5.9534247 | O18: Full time
C19: TN01281 | D19: Cletus | E19: McGarahan | F19: Female | G19: Engineering | H19: 114425.19 | I19: Above 100k | J19: 43857 | K19: 1 | L19: Permanent | M19: Wellington, New Zealand | N19: 4.4027397 | O19: Full time
... C267: VT04373 | D267: Edi | E267: Hofton | F267: Male | G267: Research and Development | H267: 28160.79 | I267: Under 50k | J267: 43129 | K267: 1 | L267: Temporary | M267: Remote | N267: 6.3972603 | O267: Full time

Sheet Q1 SumIf CountIfs
A2: 1 | B2: Total Salary and headcount by department | D2: SUMIFS, COUNTIFS | E2: Permanent headcount
B4: Below all the data has been accessed from previous staff table
B6: Department | C6: Headcount | D6: Total Salary | E6: Average Salary | F6: Employee Type | G6: Permanent Head Count | K6: Emp ID | L6: First Name | M6: Last Name | N6: Gender | O6: Department | P6: Salary | Q6: Salary Bucket | R6: Start Date | S6: FTE | T6: Employee type | U6: Work location | V6: Tenure | W6: Work Type
B7: Training | C7: {=COUNTIFS(staff[Department],B7:B18)} -> 24 | D7: {=SUMIFS(staff[Salary],staff[Department],B7:B18)} -> 2013215.2 | E7: {=AVERAGEIFS(staff[Salary],staff[Department],B7:B18)} -> 83883.965 | F7: Permanent | G7: {=COUNTIFS(staff[Employee type],F7:F9)} -> 168 | K7: PR00007 | L7: Torrance | M7: Collier | N7: Female | O7: Training | P7: 96135.75 | Q7: 50k to 100k | R7: 44025 | S7: 0.3 | T7: Permanent | U7: Wellington, New Zealand | V7: 3.9424658 | W7: Part time | Z7: Here all the data has been taken from side table
B8: Business Development | C8: 25 | D8: 1993631.2 | E8: 79745.248 | F8: Fixed Term | G8: 50 | K8: PR00095 | L8: Devrat | M8: Damarsingh | N8: Female | O8: Business Development | P8: 70649.46 | Q8: 50k to 100k | R8: 43843 | S8: 1 | T8: Permanent | U8: Hyderabad, India | V8: 4.4410959 | W8: Full time
B9: Engineering | C9: 26 | D9: 2131387.5 | E9: 81976.442 | F9: Temporary | G9: 42 | K9: PR00113 | L9: Van | M9: Tuxwell | N9: Female | O9: Business Development | P9: 80695.74 | Q9: 50k to 100k | R9: 43360 | S9: 1 | T9: Permanent | U9: Columbus, USA | V9: 5.7643836 | W9: Full time | Z9: Department | AA9: Head Count | AB9: Total Salary | AC9: Average | AD9: Employee Work Type | AE9: Work Type Head Count
B10: Marketing | C10: 12 | D10: 773295.6 | E10: 64441.3 | K10: PR00113 | L10: Van | M10: Tuxwell | N10: Female | O10: Business Development | P10: 80695.74 | Q10: 50k to 100k | R10: 43360 | S10: 1 | T10: Permanent | U10: Columbus, USA | V10: 5.7643836 | W10: Full time | Z10: Training | AA10: {=COUNTIFS(O7:O266,Z10:Z21)} -> 24 | AB10: {=SUMIFS(P7:P266,O7:O266,Z10:Z21)} -> 2013215.2 | AC10: {=AVERAGEIFS(P7:P266,O7:O266,Z10:Z21)} -> 83883.965 | AD10: Permanent | AE10: {=COUNTIFS(T7:T266,AD10:AD12)} -> 168
B11: Legal | C11: 21 | D11: 1412092.9 | E11: 67242.518 | K11: PR00147 | L11: Minerva | M11: Ricardot | N11: Male | O11: Engineering | P11: 120000 | Q11: Above 100k | R11: 43416 | S11: 1 | T11: Permanent | U11: Remote | V11: 5.6109589 | W11: Full time | Z11: Business Development | AA11: 26 | AB11: 2074327 | AC11: 79781.806 | AD11: Fixed Term | AE11: 50
B12: Accounting | C12: 26 | D12: 1814980.6 | E12: 69806.946 | K12: PR00246 | L12: Husein | M12: Augar | N12: Female | O12: Marketing | P12: 67905.8 | Q12: 50k to 100k | R12: 44194 | S12: 1 | T12: Permanent | U12: Remote | V12: 3.4794521 | W12: Full time | Z12: Engineering | AA12: 26 | AB12: 2131387.5 | AC12: 81976.442 | AD12: Temporary | AE12: 42
B13: Human Resources | C13: 22 | D13: 1608406.3 | E13: 73109.378 | K13: PR00419 | L13: Billi | M13: Fellgate | N13: Female | O13: Business Development | P13: 68980.52 | Q13: 50k to 100k | R13: 43494 | S13: 0.8 | T13: Permanent | U13: Remote | V13: 5.3972603 | W13: Part time | Z13: Marketing | AA13: 12 | AB13: 773295.6 | AC13: 64441.3
B14: Research and Development | C14: 18 | D14: 1204393.8 | E14: 66910.766 | K14: PR00576 | L14: Lalitchandra | M14: Vadali | N14: Female | O14: Legal | P14: 63705.4 | Q14: 50k to 100k | R14: 43682 | S14: 1 | T14: Permanent | U14: Hyderabad, India | V14: 4.8821918 | W14: Full time | Z14: Legal | AA14: 21 | AB14: 1412092.9 | AC14: 67242.518
B15: Services | C15: 21 | D15: 1568153.5 | E15: 74673.975 | K15: PR00746 | L15: Hogan | M15: Iles | N15: Female | O15: Accounting | P15: 114177.23 | Q15: Above 100k | R15: 43908 | S15: 1 | T15: Permanent | U15: Wellington, New Zealand | V15: 4.2630137 | W15: Full time | Z15: Accounting | AA15: 26 | AB15: 1814980.6 | AC15: 69806.946
B16: Product Management | C16: 29 | D16: 2180192.9 | E16: 75179.064 | K16: PR00770 | L16: Beryl | M16: Burnsyde | N16: Male | O16: Legal | P16: 29774.76 | Q16: Under 50k | R16: 44105 | S16: 1 | T16: Permanent | U16: Wellington, New Zealand | V16: 3.7232877 | W16: Full time | Z16: Human Resources | AA16: 22 | AB16: 1608406.3 | AC16: 73109.378
B17: Support | C17: 17 | D17: 1129351.7 | E17: 66432.456 | K17: PR00882 | L17: Jill | M17: Shipsey | N17: Male | O17: Accounting | P17: 52963.65 | Q17: 50k to 100k | R17: 44288 | S17: 0.3 | T17: Permanent | U17: Columbus, USA | V17: 3.2219178 | W17: Part time | Z17: Research and Development | AA17: 18 | AB17: 1204393.8 | AC17: 66910.766
B18: Sales | C18: 18 | D18: 1294147.7 | E18: 71897.096 | K18: PR00893 | L18: Vasavi | M18: Veeravasarapu | N18: Male | O18: Human Resources | P18: 50310.09 | Q18: 50k to 100k | R18: 44285 | S18: 0.4 | T18: Permanent | U18: Hyderabad, India | V18: 3.230137 | W18: Part time | Z18: Services | AA18: 21 | AB18: 1568153.5 | AC18: 74673.975
K19: PR00916 | L19: Inger | M19: Chapelhow | N19: Female | O19: Research and Development | P19: 84309.95 | Q19: 50k to 100k | R19: 44501 | S19: 1 | T19: Permanent | U19: Remote | V19: 2.6383562 | W19: Full time | Z19: Product Management | AA19: 29 | AB19: 2180192.9 | AC19: 75179.064
K20: PR01055 | L20: Devasree | M20: Fullara | N20: Male | O20: Accounting | P20: 35936.31 | Q20: Under 50k | R20: 43241 | S20: 1 | T20: Permanent | U20: Chennai, India | V20: 6.090411 | W20: Full time | Z20: Support | AA20: 17 | AB20: 1129351.8 | AC20: 66432.456
K21: PR01159 | L21: Mollie | M21: Hanway | N21: Male | O21: Engineering | P21: 112645.99 | Q21: Above 100k | R21: 43759 | S21: 0.6 | T21: Permanent | U21: Seattle, USA | V21: 4.6712329 | W21: Part time | Z21: Sales | AA21: 18 | AB21: 1294147.7 | AC21: 71897.096
K22: PR01211 | L22: Enoch | M22: Dowrey | N22: Male | O22: Accounting | P22: 91645.04 | Q22: 50k to 100k | R22: 44223 | S22: 1 | T22: Permanent | U22: Auckland, New Zealand | V22: 3.4 | W22: Full time
K23: PR01269 | L23: Eleonore | M23: Airdrie | N23: Female | O23: Engineering | P23: 97105.19 | Q23: 50k to 100k | R23: 44425 | S23: 1 | T23: Permanent | U23: Columbus, USA | V23: 2.8465753 | W23: Full time
K24: PR01306 | L24: Patti | M24: Dradey | N24: Male | O24: Services | P24: 84742.86 | Q24: 50k to 100k | R24: 44098 | S24: 1 | T24: Permanent | U24: Auckland, New Zealand | V24: 3.7424658 | W24: Full time
K25: PR01346 | L25: Adolph | M25: McNalley | N25: Male | O25: Business Development | P25: 85918.61 | Q25: 50k to 100k | R25: 43136 | S25: 1 | T25: Permanent | U25: Columbus, USA | V25: 6.3780822 | W25: Full time
K26: PR01383 | L26: Addi | M26: Studdeard | N26: Female | O26: Product Management | P26: 72502.61 | Q26: 50k to 100k | R26: 44235 | S26: 1 | T26: Permanent | U26: Wellington, New Zealand | V26: 3.3671233 | W26: Full time
K27: PR01476 | L27: Jaishree | M27: Atasi | N27: Male | O27: Services | P27: 77096.05 | Q27: 50k to 100k | R27: 43217 | S27: 1 | T27: Permanent | U27: Chennai, India | V27: 6.1561644 | W27: Full time
K28: PR01662 | L28: Genevra | M28: Friday | N28: Female | O28: Research and Development | P28: 50449.46 | Q28: 50k to 100k | R28: 43418 | S28: 0.8 | T28: Permanent | U28: Auckland, New Zealand | V28: 5.6054795 | W28: Part time
K29: PR01943 | L29: Rameshwari | M29: Chikodi | N29: Male | O29: Human Resources | P29: 48525.71 | Q29: Under 50k | R29: 43264 | S29: 1 | T29: Permanent | U29: Hyderabad, India | V29: 6.0273973 | W29: Full time
K30: PR01956 | L30: Jamesy | M30: O'Ferris | N30: Male | O30: Accounting | P30: 36547.58 | Q30: Under 50k | R30: 43416 | S30: 1 | T30: Permanent | U30: Remote | V30: 5.6109589 | W30: Full time
K31: PR01956 | L31: Jamesy | M31: O'Ferris | N31: Male | O31: Accounting | P31: 36547.58 | Q31: Under 50k | R31: 43416 | S31: 1 | T31: Permanent | U31: Remote | V31: 5.6109589 | W31: Full time
K32: PR02010 | L32: Prerana | M32: Nishita | N32: Male | O32: Product Management | P32: 115191.38 | Q32: Above 100k | R32: 44004 | S32: 1 | T32: Permanent | U32: Hyderabad, India | V32: 4 | W32: Full time
K33: PR02016 | L33: Iris | M33: Wagg | N33: Female | O33: Engineering | P33: 58861.19 | Q33: 50k to 100k | R33: 43654 | S33: 1 | T33: Permanent | U33: Columbus, USA | V33: 4.9589041 | W33: Full time
... K266: VT04984 | L266: Dell | M266: Molloy | N266: Male | O266: Engineering | P266: 47362.62 | Q266: Under 50k | R266: 43973 | S266: 1 | T266: Temporary | U266: Remote | V266: 4.0849315 | W266: Full time

Sheet Q2 Large,Filter, Take, Sort
A1: All employees with more than $100k salary | E1: FILTER
B5: {=staff[#Headers]} -> Emp ID | C5: First Name | D5: Last Name | E5: Gender | F5: Department | G5: Salary | H5: Salary Bucket | I5: Start Date | J5: FTE | K5: Employee type | L5: Work location | M5: Tenure | N5: Work Type | Z5: First Name | AA5: Last Name | AB5: Gender | AC5: Department | AD5: Salary | AE5: Salary Bucket | AF5: Start Date | AG5: FTE | AH5: Employee type | AI5: Work location | AJ5: Tenure | AK5: Work Type
B6: {=_xlfn._xlws.FILTER(staff[],staff[Salary]>100000)} -> PR00147 | C6: Minerva | D6: Ricardot | E6: Male | F6: Engineering | G6: 120000 | H6: Above 100k | I6: 43416 | J6: 1 | K6: Permanent | L6: Remote | M6: 5.6109589 | N6: Full time | S6: {=COLUMN(G5:G52)} -> 7 | Z6: Torrance | AA6: Collier | AB6: Female | AC6: Training | AD6: 96135.75 | AE6: 50k to 100k | AF6: 44025 | AG6: 0.3 | AH6: Permanent | AI6: Wellington, New Zealand | AJ6: 3.9424658 | AK6: Part time | AP6: This Table is came from side table using filter formula
B7: SQ04612 | C7: Mick | D7: Spraberry | E7: Female | F7: Services | G7: 120000 | H7: Above 100k | I7: 43902 | J7: 0.9 | K7: Permanent | L7: Remote | M7: 4.2794521 | N7: Part time | Q7: finding top 10 salaries | V7: {=_xlfn.SEQUENCE(10)} -> 1 | Z7: Devrat | AA7: Damarsingh | AB7: Female | AC7: Business Development | AD7: 70649.46 | AE7: 50k to 100k | AF7: 43843 | AG7: 1 | AH7: Permanent | AI7: Hyderabad, India | AJ7: 4.4410959 | AK7: Full time
B8: PR03886 | C8: Edd | D8: MacKnockiter | E8: Male | F8: Accounting | G8: 119022.49 | H8: Above 100k | I8: 44431 | J8: 1 | K8: Permanent | L8: Auckland, New Zealand | M8: 2.830137 | N8: Full time | V8: 2 | Z8: Van | AA8: Tuxwell | AB8: Female | AC8: Business Development | AD8: 80695.74 | AE8: 50k to 100k | AF8: 43360 | AG8: 1 | AH8: Permanent | AI8: Columbus, USA | AJ8: 5.7643836 | AK8: Full time | AN8: {=_xlfn._xlws.FILTER(Z5:AK266,AD5:AD266>100000)} -> First Name | AO8: Last Name | AP8: Gender | AQ8: Department | AR8: Salary | AS8: Salary Bucket | AT8: Start Date | AU8: FTE | AV8: Employee type | AW8: Work location | AX8: Tenure | AY8: Work Type
B9: SQ00144 | C9: Collen | D9: Dunbleton | E9: Male | F9: Engineering | G9: 118976.16 | H9: Above 100k | I9: 44120 | J9: 1 | K9: Permanent | L9: Wellington, New Zealand | M9: 3.6821918 | N9: Full time | Q9: Large & Filter | R9: Take + Sort | V9: 3 | Z9: Van | AA9: Tuxwell | AB9: Female | AC9: Business Development | AD9: 80695.74 | AE9: 50k to 100k | AF9: 43360 | AG9: 1 | AH9: Permanent | AI9: Columbus, USA | AJ9: 5.7643836 | AK9: Full time | AN9: Minerva | AO9: 0 | AP9: Male | AQ9: Engineering | AR9: 120000 | AS9: Above 100k | AT9: 43416 | AU9: 1 | AV9: Permanent | AW9: Remote | AX9: 5.6109589 | AY9: Full time
B10: SQ02174 | C10: Sidoney | D10: Yitzhok | E10: Female | F10: Engineering | G10: 118442.54 | H10: Above 100k | I10: 44193 | J10: 1 | K10: Permanent | L10: Auckland, New Zealand | M10: 3.4821918 | N10: Full time | Q10: {=LARGE(_xlfn._xlws.FILTER('Q2 Large,Filter, Take, Sort'!$B$5:$N$52,('Q2 Large,Filter, Take, Sort'!$E$5:$E$52)="Male"),'Q2 Large,Filter, Take, Sort'!V7)} -> 120000 | R10: {=_xlfn.TAKE(_xlfn._xlws.SORT(G6:G52,,1),10)} -> 100371.31 | T10: =MIN(G6:G52) -> 100371.31 | V10: 4 | Z10: Minerva | AB10: Male | AC10: Engineering | AD10: 120000 | AE10: Above 100k | AF10: 43416 | AG10: 1 | AH10: Permanent | AI10: Remote | AJ10: 5.6109589 | AK10: Full time | AN10: Hogan | AO10: Iles | AP10: Female | AQ10: Accounting | AR10: 114177.23 | AS10: Above 100k | AT10: 43908 | AU10: 1 | AV10: Permanent | AW10: Wellington, New Zealand | AX10: 4.2630137 | AY10: Full time
B11: VT04093 | C11: Prasanna | D11: Lakshmi | E11: Female | F11: Training | G11: 116767.63 | H11: Above 100k | I11: 43949 | J11: 0.4 | K11: Temporary | L11: Chennai, India | M11: 4.1506849 | N11: Part time | Q11: {=LARGE(_xlfn._xlws.FILTER('Q2 Large,Filter, Take, Sort'!$B$5:$N$52,('Q2 Large,Filter, Take, Sort'!$E$5:$E$52)="Male"),'Q2 Large,Filter, Take, Sort'!V8)} -> 119022.49 | R11: 100424.23 | T11: =MAX(G6:G52) -> 120000 | V11: 5 | Z11: Husein | AA11: Augar | AB11: Female | AC11: Marketing | AD11: 67905.8 | AE11: 50k to 100k | AF11: 44194 | AG11: 1 | AH11: Permanent | AI11: Remote | AJ11: 3.4794521 | AK11: Full time | AN11: Mollie | AO11: Hanway | AP11: Male | AQ11: Engineering | AR11: 112645.99 | AS11: Above 100k | AT11: 43759 | AU11: 0.6 | AV11: Permanent | AW11: Seattle, USA | AX11: 4.6712329 | AY11: Part time
B12: VT04093 | C12: Baruna | D12: Ogale | E12: Female | F12: Training | G12: 116767.63 | H12: Above 100k | I12: 43949 | J12: 0.4 | K12: Temporary | L12: Chennai, India | M12: 4.1506849 | N12: Part time | Q12: {=LARGE(_xlfn._xlws.FILTER('Q2 Large,Filter, Take, Sort'!$B$5:$N$52,('Q2 Large,Filter, Take, Sort'!$E$5:$E$52)="Male"),'Q2 Large,Filter, Take, Sort'!V9)} -> 118976.16 | R12: 100731.95 | T12: {=LARGE(_xlfn._xlws.FILTER(G6:G52,E6:E52="Male"),V7)} -> 120000 | V12: 6 | Z12: Billi | AA12: Fellgate | AB12: Female | AC12: Business Development | AD12: 68980.52 | AE12: 50k to 100k | AF12: 43494 | AG12: 0.8 | AH12: Permanent | AI12: Remote | AJ12: 5.3972603 | AK12: Part time | AN12: Prerana | AO12: Nishita | AP12: Male | AQ12: Product Management | AR12: 115191.38 | AS12: Above 100k | AT12: 44004 | AU12: 1 | AV12: Permanent | AW12: Hyderabad, India | AX12: 4 | AY12: Full time
B13: PR02010 | C13: Prerana | D13: Nishita | E13: Male | F13: Product Management | G13: 115191.38 | H13: Above 100k | I13: 44004 | J13: 1 | K13: Permanent | L13: Hyderabad, India | M13: 4 | N13: Full time | Q13: {=LARGE(_xlfn._xlws.FILTER('Q2 Large,Filter, Take, Sort'!$B$5:$N$52,('Q2 Large,Filter, Take, Sort'!$E$5:$E$52)="Male"),'Q2 Large,Filter, Take, Sort'!V10)} -> 115191.38 | R13: 101187.36 | T13: {=LARGE(_xlfn._xlws.FILTER(G7:G53,E7:E53="Male"),V8)} -> 118976.16 | V13: 7 | Z13: Lalitchandra | AA13: Vadali | AB13: Female | AC13: Legal | AD13: 63705.4 | AE13: 50k to 100k | AF13: 43682 | AG13: 1 | AH13: Permanent | AI13: Hyderabad, India | AJ13: 4.8821918 | AK13: Full time | AN13: Gowri | AO13: Sankar | AP13: Female | AQ13: Training | AR13: 102934.09 | AS13: Above 100k | AT13: 44315 | AU13: 1 | AV13: Permanent | AW13: Hyderabad, India | AX13: 3.1479452 | AY13: Full time
B14: SQ02624 | C14: Gwenneth | D14: Fealey | E14: Female | F14: Engineering | G14: 114772.32 | H14: Above 100k | I14: 44251 | J14: 1 | K14: Permanent | L14: Columbus, USA | M14: 3.3232877 | N14: Full time | Q14: {=LARGE(_xlfn._xlws.FILTER('Q2 Large,Filter, Take, Sort'!$B$5:$N$52,('Q2 Large,Filter, Take, Sort'!$E$5:$E$52)="Male"),'Q2 Large,Filter, Take, Sort'!V11)} -> 114691.03 | R14: 102129.37 | T14: {=LARGE(_xlfn._xlws.FILTER(G8:G54,E8:E54="Male"),V9)} -> 115191.38 | V14: 8 | Z14: Hogan | AA14: Iles | AB14: Female | AC14: Accounting | AD14: 114177.23 | AE14: Above 100k | AF14: 43908 | AG14: 1 | AH14: Permanent | AI14: Wellington, New Zealand | AJ14: 4.2630137 | AK14: Full time | AN14: Althea | AO14: Bronger | AP14: Male | AQ14: Product Management | AR14: 104335.04 | AS14: Above 100k | AT14: 43874 | AU14: 1 | AV14: Permanent | AW14: Columbus, USA | AX14: 4.3561644 | AY14: Full time
B15: VT02801 | C15: Shellysheldon | D15: Mahady | E15: Male | F15: Training | G15: 114691.03 | H15: Above 100k | I15: 44039 | J15: 1 | K15: Temporary | L15: Wellington, New Zealand | M15: 3.9041096 | N15: Full time | Q15: {=LARGE(_xlfn._xlws.FILTER('Q2 Large,Filter, Take, Sort'!$B$5:$N$52,('Q2 Large,Filter, Take, Sort'!$E$5:$E$52)="Male"),'Q2 Large,Filter, Take, Sort'!V12)} -> 114465.93 | R15: 102515.81 | T15: {=LARGE(_xlfn._xlws.FILTER(G9:G55,E9:E55="Male"),V10)} -> 114465.93 | V15: 9 | Z15: Beryl | AA15: Burnsyde | AB15: Male | AC15: Legal | AD15: 29774.76 | AE15: Under 50k | AF15: 44105 | AG15: 1 | AH15: Permanent | AI15: Wellington, New Zealand | AJ15: 3.7232877 | AK15: Full time | AN15: Edd | AO15: MacKnockiter | AP15: Male | AQ15: Accounting | AR15: 119022.49 | AS15: Above 100k | AT15: 44431 | AU15: 1 | AV15: Permanent | AW15: Auckland, New Zealand | AX15: 2.830137 | AY15: Full time
B16: VT02491 | C16: Alexis | D16: Gotfrey | E16: Male | F16: Engineering | G16: 114465.93 | H16: Above 100k | I16: 43291 | J16: 1 | K16: Temporary | L16: Wellington, New Zealand | M16: 5.9534247 | N16: Full time | Q16: {=LARGE(_xlfn._xlws.FILTER('Q2 Large,Filter, Take, Sort'!$B$5:$N$52,('Q2 Large,Filter, Take, Sort'!$E$5:$E$52)="Male"),'Q2 Large,Filter, Take, Sort'!V13)} -> 113747.56 | R16: 102934.09 | T16: {=LARGE(_xlfn._xlws.FILTER(G10:G56,E10:E56="Male"),V11)} -> 113747.56 | V16: 10 | Z16: Jill | AA16: Shipsey | AB16: Male | AC16: Accounting | AD16: 52963.65 | AE16: 50k to 100k | AF16: 44288 | AG16: 0.3 | AH16: Permanent | AI16: Columbus, USA | AJ16: 3.2219178 | AK16: Part time | AN16: Yedukondalu | AO16: Panditula | AP16: Need to check | AQ16: Support | AR16: 104802.63 | AS16: Above 100k | AT16: 44502 | AU16: 1 | AV16: Permanent | AW16: Hyderabad, India | AX16: 2.6356164 | AY16: Full time
B17: TN01281 | C17: Cletus | D17: McGarahan | E17: Female | F17: Engineering | G17: 114425.19 | H17: Above 100k | I17: 43857 | J17: 1 | K17: Permanent | L17: Wellington, New Zealand | M17: 4.4027397 | N17: Full time | Q17: {=LARGE(_xlfn._xlws.FILTER('Q2 Large,Filter, Take, Sort'!$B$5:$N$52,('Q2 Large,Filter, Take, Sort'!$E$5:$E$52)="Male"),'Q2 Large,Filter, Take, Sort'!V14)} -> 113747.56 | R17: 103494.94 | T17: {=LARGE(_xlfn._xlws.FILTER(G11:G57,E11:E57="Male"),V12)} -> 113616.23 | V17: 11 | Z17: Vasavi | AA17: Veeravasarapu | AB17: Male | AC17: Human Resources | AD17: 50310.09 | AE17: 50k to 100k | AF17: 44285 | AG17: 0.4 | AH17: Permanent | AI17: Hyderabad, India | AJ17: 3.230137 | AK17: Part time | AN17: Carlin | AO17: Demke | AP17: Male | AQ17: Business Development | AR17: 110042.37 | AS17: Above 100k | AT17: 43914 | AU17: 1 | AV17: Permanent | AW17: Columbus, USA | AX17: 4.2465753 | AY17: Full time
B18: PR00746 | C18: Hogan | D18: Iles | E18: Female | F18: Accounting | G18: 114177.23 | H18: Above 100k | I18: 43908 | J18: 1 | K18: Permanent | L18: Wellington, New Zealand | M18: 4.2630137 | N18: Full time | Q18: {=LARGE(_xlfn._xlws.FILTER('Q2 Large,Filter, Take, Sort'!$B$5:$N$52,('Q2 Large,Filter, Take, Sort'!$E$5:$E$52)="Male"),'Q2 Large,Filter, Take, Sort'!V15)} -> 113616.23 | R18: 103494.94 | T18: {=LARGE(_xlfn._xlws.FILTER(G12:G58,E12:E58="Male"),V13)} -> 112778.28 | Z18: Inger | AA18: Chapelhow | AB18: Female | AC18: Research and Development | AD18: 84309.95 | AE18: 50k to 100k | AF18: 44501 | AG18: 1 | AH18: Permanent | AI18: Remote | AJ18: 2.6383562 | AK18: Full time | AN18: Collen | AO18: Dunbleton | AP18: Male | AQ18: Engineering | AR18: 118976.16 | AS18: Above 100k | AT18: 44120 | AU18: 1 | AV18: Permanent | AW18: Wellington, New Zealand | AX18: 3.6821918 | AY18: Full time
B19: VT03421 | C19: Alic | D19: Bagg | E19: Male | F19: Legal | G19: 113747.56 | H19: Above 100k | I19: 44270 | J19: 0.7 | K19: Temporary | L19: Columbus, USA | M19: 3.2712329 | N19: Part time | Q19: {=LARGE(_xlfn._xlws.FILTER('Q2 Large,Filter, Take, Sort'!$B$5:$N$52,('Q2 Large,Filter, Take, Sort'!$E$5:$E$52)="Male"),'Q2 Large,Filter, Take, Sort'!V16)} -> 112778.28 | R19: 104038.9 | T19: {=LARGE(_xlfn._xlws.FILTER(G13:G59,E13:E59="Male"),V14)} -> 112778.28 | Z19: Devasree | AA19: Fullara | AB19: Male | AC19: Accounting | AD19: 35936.31 | AE19: Under 50k | AF19: 43241 | AG19: 1 | AH19: Permanent | AI19: Chennai, India | AJ19: 6.090411 | AK19: Full time | AN19: Amery | AO19: Ofer | AP19: Female | AQ19: Legal | AR19: 111049.84 | AS19: Above 100k | AT19: 44393 | AU19: 1 | AV19: Permanent | AW19: Wellington, New Zealand | AX19: 2.9342466 | AY19: Full time
B20: VT03421 | C20: Alic | D20: Bagg | E20: Male | F20: Legal | G20: 113747.56 | H20: Above 100k | I20: 44270 | J20: 0.7 | K20: Temporary | L20: Columbus, USA | M20: 3.2712329 | N20: Part time | Q20: {=LARGE(_xlfn._xlws.FILTER('Q2 Large,Filter, Take, Sort'!$B$5:$N$52,('Q2 Large,Filter, Take, Sort'!$E$5:$E$52)="Male"),'Q2 Large,Filter, Take, Sort'!V17)} -> 112778.28 | T20: {=LARGE(_xlfn._xlws.FILTER(G14:G60,E14:E60="Male"),V15)} -> 111815.49 | Z20: Mollie | AA20: Hanway | AB20: Male | AC20: Engineering | AD20: 112645.99 | AE20: Above 100k | AF20: 43759 | AG20: 0.6 | AH20: Permanent | AI20: Seattle, USA | AJ20: 4.6712329 | AK20: Part time | AN20: Westbrook | AO20: Brandino | AP20: Male | AQ20: Legal | AR20: 113616.23 | AS20: Above 100k | AT20: 43255 | AU20: 1 | AV20: Permanent | AW20: Remote | AX20: 6.0520548 | AY20: Full time
B21: SQ01620 | C21: Westbrook | D21: Brandino | E21: Male | F21: Legal | G21: 113616.23 | H21: Above 100k | I21: 43255 | J21: 1 | K21: Permanent | L21: Remote | M21: 6.0520548 | N21: Full time | T21: {=LARGE(_xlfn._xlws.FILTER(G15:G61,E15:E61="Male"),V16)} -> 111815.49 | Z21: Enoch | AA21: Dowrey | AB21: Male | AC21: Accounting | AD21: 91645.04 | AE21: 50k to 100k | AF21: 44223 | AG21: 1 | AH21: Permanent | AI21: Auckland, New Zealand | AJ21: 3.4 | AK21: Full time | AN21: Anni | AO21: Izzard | AP21: Male | AQ21: Human Resources | AR21: 103494.94 | AS21: Above 100k | AT21: 43256 | AU21: 1 | AV21: Permanent | AW21: Remote | AX21: 6.0493151 | AY21: Full time
B22: VT01893 | C22: Lindy | D22: Guillet | E22: Male | F22: Training | G22: 112778.28 | H22: Above 100k | I22: 43250 | J22: 1 | K22: Fixed Term | L22: Remote | M22: 6.0657534 | N22: Full time | T22: {=LARGE(_xlfn._xlws.FILTER(G16:G62,E16:E62="Male"),V17)} -> 110042.37 | Z22: Eleonore | AA22: Airdrie | AB22: Female | AC22: Engineering | AD22: 97105.19 | AE22: 50k to 100k | AF22: 44425 | AG22: 1 | AH22: Permanent | AI22: Columbus, USA | AJ22: 2.8465753 | AK22: Full time | AN22: Anni | AO22: Izzard | AP22: Male | AQ22: Human Resources | AR22: 103494.94 | AS22: Above 100k | AT22: 43256 | AU22: 1 | AV22: Permanent | AW22: Remote | AX22: 6.0493151 | AY22: Full time
B23: VT01893 | C23: Lindy | D23: Guillet | E23: Male | F23: Training | G23: 112778.28 | H23: Above 100k | I23: 43250 | J23: 1 | K23: Fixed Term | L23: Remote | M23: 6.0657534 | N23: Full time | T23: {=LARGE(_xlfn._xlws.FILTER(G17:G63,E17:E63="Male"),V18)} -> #NUM! | Z23: Patti | AA23: Dradey | AB23: Male | AC23: Services | AD23: 84742.86 | AE23: 50k to 100k | AF23: 44098 | AG23: 1 | AH23: Permanent | AI23: Auckland, New Zealand | AJ23: 3.7424658 | AK23: Full time | AN23: Sidoney | AO23: Yitzhok | AP23: Female | AQ23: Engineering | AR23: 118442.54 | AS23: Above 100k | AT23: 44193 | AU23: 1 | AV23: Permanent | AW23: Auckland, New Zealand | AX23: 3.4821918 | AY23: Full time
B24: PR01159 | C24: Mollie | D24: Hanway | E24: Male | F24: Engineering | G24: 112645.99 | H24: Above 100k | I24: 43759 | J24: 0.6 | K24: Permanent | L24: Seattle, USA | M24: 4.6712329 | N24: Part time | T24: {=LARGE(_xlfn._xlws.FILTER(G18:G64,E18:E64="Male"),V19)} -> #NUM! | Z24: Adolph | AA24: McNalley | AB24: Male | AC24: Business Development | AD24: 85918.61 | AE24: 50k to 100k | AF24: 43136 | AG24: 1 | AH24: Permanent | AI24: Columbus, USA | AJ24: 6.3780822 | AK24: Full time | AN24: Gwenneth | AO24: Fealey | AP24: Female | AQ24: Engineering | AR24: 114772.32 | AS24: Above 100k | AT24: 44251 | AU24: 1 | AV24: Permanent | AW24: Columbus, USA | AX24: 3.3232877 | AY24: Full time
B25: VT04028 | C25: Michale | D25: Rolf | E25: Male | F25: Services | G25: 111815.49 | H25: Above 100k | I25: 43895 | J25: 0.7 | K25: Temporary | L25: Remote | M25: 4.2986301 | N25: Part time | Z25: Addi | AA25: Studdeard | AB25: Female | AC25: Product Management | AD25: 72502.61 | AE25: 50k to 100k | AF25: 44235 | AG25: 1 | AH25: Permanent | AI25: Wellington, New Zealand | AJ25: 3.3671233 | AK25: Full time | AN25: Deepit | AO25: Ranjana | AP25: Female | AQ25: Marketing | AR25: 104903.79 | AS25: Above 100k | AT25: 43649 | AU25: 1 | AV25: Permanent | AW25: Chennai, India | AX25: 4.9726027 | AY25: Full time
B26: VT04028 | C26: Michale | D26: Rolf | E26: Male | F26: Services | G26: 111815.49 | H26: Above 100k | I26: 43895 | J26: 0.7 | K26: Temporary | L26: Remote | M26: 4.2986301 | N26: Part time | Z26: Jaishree | AA26: Atasi | AB26: Male | AC26: Services | AD26: 77096.05 | AE26: 50k to 100k | AF26: 43217 | AG26: 1 | AH26: Permanent | AI26: Chennai, India | AJ26: 6.1561644 | AK26: Full time | AN26: Syd | AO26: Fearn | AP26: Male | AQ26: Engineering | AR26: 108872.77 | AS26: Above 100k | AT26: 43521 | AU26: 1 | AV26: Permanent | AW26: Remote | AX26: 5.3232877 | AY26: Full time
B27: SQ04603 | C27: Natalee | D27: Craiker | E27: Male | F27: Product Management | G27: 111229.47 | H27: Above 100k | I27: 43402 | J27: 1 | K27: Permanent | L27: Remote | M27: 5.6493151 | N27: Full time | Z27: Genevra | AA27: Friday | AB27: Female | AC27: Research and Development | AD27: 50449.46 | AE27: 50k to 100k | AF27: 43418 | AG27: 0.8 | AH27: Permanent | AI27: Auckland, New Zealand | AJ27: 5.6054795 | AK27: Part time | AN27: Robinia | AO27: Scholling | AP27: Female | AQ27: Human Resources | AR27: 100731.95 | AS27: Above 100k | AT27: 43936 | AU27: 1 | AV27: Permanent | AW27: Auckland, New Zealand | AX27: 4.1863014 | AY27: Full time
B28: SQ00498 | C28: Amery | D28: Ofer | E28: Female | F28: Legal | G28: 111049.84 | H28: Above 100k | I28: 44393 | J28: 1 | K28: Permanent | L28: Wellington, New Zealand | M28: 2.9342466 | N28: Full time | Z28: Rameshwari | AA28: Chikodi | AB28: Male | AC28: Human Resources | AD28: 48525.71 | AE28: Under 50k | AF28: 43264 | AG28: 1 | AH28: Permanent | AI28: Hyderabad, India | AJ28: 6.0273973 | AK28: Full time | AN28: Ramalingam | AO28: Kothapeta | AP28: Need to check | AQ28: Accounting | AR28: 107107.6 | AS28: Above 100k | AT28: 43325 | AU28: 0.9 | AV28: Permanent | AW28: Chennai, India | AX28: 5.860274 | AY28: Part time
B29: VT04681 | C29: Nickolai | D29: Artin | E29: Female | F29: Product Management | G29: 110906.35 | H29: Above 100k | I29: 43434 | J29: 1 | K29: Temporary | L29: Wellington, New Zealand | M29: 5.5616438 | N29: Full time | Z29: Jamesy | AA29: O'Ferris | AB29: Male | AC29: Accounting | AD29: 36547.58 | AE29: Under 50k | AF29: 43416 | AG29: 1 | AH29: Permanent | AI29: Remote | AJ29: 5.6109589 | AK29: Full time | AN29: Freda | AO29: Legan | AP29: Female | AQ29: Sales | AR29: 102129.37 | AS29: Above 100k | AT29: 44396 | AU29: 1 | AV29: Permanent | AW29: Columbus, USA | AX29: 2.9260274 | AY29: Full time
B30: SQ00022 | C30: Carlin | D30: Demke | E30: Male | F30: Business Development | G30: 110042.37 | H30: Above 100k | I30: 43914 | J30: 1 | K30: Permanent | L30: Columbus, USA | M30: 4.2465753 | N30: Full time | Z30: Jamesy | AA30: O'Ferris | AB30: Male | AC30: Accounting | AD30: 36547.58 | AE30: Under 50k | AF30: 43416 | AG30: 1 | AH30: Permanent | AI30: Remote | AJ30: 5.6109589 | AK30: Full time | AN30: Revkah | AO30: Antonacci | AP30: Male | AQ30: Engineering | AR30: 109143.17 | AS30: Above 100k | AT30: 43945 | AU30: 1 | AV30: Permanent | AW30: Wellington, New Zealand | AX30: 4.1616438 | AY30: Full time
B31: TN00579 | C31: Rafaelita | D31: Blaksland | E31: Female | F31: Services | G31: 109163.39 | H31: Above 100k | I31: 44019 | J31: 0.8 | K31: Permanent | L31: Seattle, USA | M31: 3.9589041 | N31: Part time | Z31: Prerana | AA31: Nishita | AB31: Male | AC31: Product Management | AD31: 115191.38 | AE31: Above 100k | AF31: 44004 | AG31: 1 | AH31: Permanent | AI31: Hyderabad, India | AJ31: 4 | AK31: Full time | AN31: Natalee | AO31: Craiker | AP31: Male | AQ31: Product Management | AR31: 111229.47 | AS31: Above 100k | AT31: 43402 | AU31: 1 | AV31: Permanent | AW31: Remote | AX31: 5.6493151 | AY31: Full time
B32: SQ03733 | C32: Revkah | D32: Antonacci | E32: Male | F32: Engineering | G32: 109143.17 | H32: Above 100k | I32: 43945 | J32: 1 | K32: Permanent | L32: Wellington, New Zealand | M32: 4.1616438 | N32: Full time | Z32: Iris | AA32: Wagg | AB32: Female | AC32: Engineering | AD32: 58861.19 | AE32: 50k to 100k | AF32: 43654 | AG32: 1 | AH32: Permanent | AI32: Columbus, USA | AJ32: 4.9589041 | AK32: Full time | AN32: Mick | AO32: Spraberry | AP32: Female | AQ32: Services | AR32: 120000 | AS32: Above 100k | AT32: 43902 | AU32: 0.9 | AV32: Permanent | AW32: Remote | AX32: 4.2794521 | AY32: Part time
B33: SQ03116 | C33: Syd | D33: Fearn | E33: Male | F33: Engineering | G33: 108872.77 | H33: Above 100k | I33: 43521 | J33: 1 | K33: Permanent | L33: Remote | M33: 5.3232877 | N33: Full time | Z33: Beverie | AA33: Moffet | AB33: Female | AC33: Support | AD33: 75974.99 | AE33: 50k to 100k | AF33: 44172 | AG33: 1 | AH33: Permanent | AI33: Remote | AJ33: 3.539726 | AK33: Full time | AN33: Collin | AO33: Jagson | AP33: Male | AQ33: Services | AR33: 100424.23 | AS33: Above 100k | AT33: 43801 | AU33: 1 | AV33: Permanent | AW33: Auckland, New Zealand | AX33: 4.5561644 | AY33: Full time
B34: SQ03476 | C34: Ramalingam | D34: Kothapeta | E34: Need to check | F34: Accounting | G34: 107107.6 | H34: Above 100k | I34: 43325 | J34: 0.9 | K34: Permanent | L34: Chennai, India | M34: 5.860274 | N34: Part time | Z34: Anjushri | AA34: Chandiramani | AB34: Male | AC34: Accounting | AD34: 95954.02 | AE34: 50k to 100k | AF34: 43567 | AG34: 0.3 | AH34: Permanent | AI34: Hyderabad, India | AJ34: 5.1972603 | AK34: Part time | AN34: Rafaelita | AO34: Blaksland | AP34: Female | AQ34: Services | AR34: 109163.39 | AS34: Above 100k | AT34: 44019 | AU34: 0.8 | AV34: Permanent | AW34: Seattle, USA | AX34: 3.9589041 | AY34: Part time
B35: TN04058 | C35: Subbarao | D35: Malladi | E35: Male | F35: Product Management | G35: 106775.14 | H35: Above 100k | I35: 43563 | J35: 1 | K35: Fixed Term | L35: Hyderabad, India | M35: 5.2082192 | N35: Full time | Z35: Gowri | AA35: Sankar | AB35: Female | AC35: Training | AD35: 102934.09 | AE35: Above 100k | AF35: 44315 | AG35: 1 | AH35: Permanent | AI35: Hyderabad, India | AJ35: 3.1479452 | AK35: Full time | AN35: Cletus | AO35: McGarahan | AP35: Female | AQ35: Engineering | AR35: 114425.19 | AS35: Above 100k | AT35: 43857 | AU35: 1 | AV35: Permanent | AW35: Wellington, New Zealand | AX35: 4.4027397 | AY35: Full time
B36: TN04058 | C36: Vasu | D36: Nandin | E36: Male | F36: Product Management | G36: 106775.14 | H36: Above 100k | I36: 43563 | J36: 1 | K36: Fixed Term | L36: Hyderabad, India | M36: 5.2082192 | N36: Full time | Z36: Louise | AA36: Lamming | AB36: Female | AC36: Sales | AD36: 41934.71 | AE36: Under 50k | AF36: 43780 | AG36: 1 | AH36: Permanent | AI36: Remote | AJ36: 4.6136986 | AK36: Full time | AN36: Subbarao | AO36: Malladi | AP36: Male | AQ36: Product Management | AR36: 106775.14 | AS36: Above 100k | AT36: 43563 | AU36: 1 | AV36: Fixed Term | AW36: Hyderabad, India | AX36: 5.2082192 | AY36: Full time
... B52: TN04246 | C52: Shaylyn | D52: Ransbury | E52: Female | F52: Support | G52: 100371.31 | H52: Above 100k | I52: 44067 | J52: 0.8 | K52: Fixed Term | L52: Auckland, New Zealand | M52: 3.8273973 | N52: Part time | Z52: Edd | AA52: MacKnockiter | AB52: Male | AC52: Accounting | AD52: 119022.49 | AE52: Above 100k | AF52: 44431 | AG52: 1 | AH52: Permanent | AI52: Auckland, New Zealand | AJ52: 2.830137 | AK52: Full time | AN52: Kulbhushan | AO52: Moorthy | AP52: Male | AQ52: Business Development | AR52: 106400.02 | AS52: Above 100k | AT52: 44021 | AU52: 1 | AV52: Temporary | AW52: Chennai, India | AX52: 3.9534247 | AY52: Full time
Z53: Kath | AA53: Bletsoe | AB53: Male | AC53: Marketing | AD53: 65699.02 | AE53: 50k to 100k | AF53: 43951 | AG53: 1 | AH53: Permanent | AI53: Columbus, USA | AJ53: 4.1452055 | AK53: Full time | AN53: Lalit | AO53: Kothari | AP53: Male | AQ53: Business Development | AR53: 106400.02 | AS53: Above 100k | AT53: 44021 | AU53: 1 | AV53: Temporary | AW53: Chennai, India | AX53: 3.9534247 | AY53: Full time
Z54: Carry | AA54: Loblie | AB54: Female | AC54: Sales | AD54: 47551.89 | AE54: Under 50k | AF54: 43468 | AG54: 1 | AH54: Permanent | AI54: Auckland, New Zealand | AJ54: 5.4684932 | AK54: Full time | AN54: Theresita | AO54: Chasmer | AP54: Female | AQ54: Product Management | AR54: 106665.67 | AS54: Above 100k | AT54: 43311 | AU54: 1 | AV54: Temporary | AW54: Columbus, USA | AX54: 5.8986301 | AY54: Full time
Z55: Van | AA55: Tuxwell | AB55: Female | AC55: Business Development | AD55: 80695.74 | AE55: 50k to 100k | AF55: 43787 | AG55: 0.8 | AH55: Permanent | AI55: Columbus, USA | AJ55: 4.5945205 | AK55: Part time | AN55: Nickolai | AO55: Artin | AP55: Female | AQ55: Product Management | AR55: 110906.35 | AS55: Above 100k | AT55: 43434 | AU55: 1 | AV55: Temporary | AW55: Wellington, New Zealand | AX55: 5.5616438 | AY55: Full time
B56: All Employee With >100K Salary | Z56: Sameer | AA56: Shashank | AB56: Female | AC56: Research and Development | AD56: 92336.08 | AE56: 50k to 100k | AF56: 44431 | AG56: 1 | AH56: Permanent | AI56: Hyderabad, India | AJ56: 2.830137 | AK56: Full time
B57: Want only subset data col - 1, 2, 3, 5, 6 | F57: First we use filter form. Then use choose form | Z57: Wyn | AA57: Treadger | AB57: Female | AC57: Business Development | AD57: 69192.85 | AE57: 50k to 100k | AF57: 44305 | AG57: 1 | AH57: Permanent | AI57: Columbus, USA | AJ57: 3.1753425 | AK57: Full time
C58: write value to see the data | E58: 100000 | Z58: Yedukondalu | AA58: Panditula | AB58: Need to check | AC58: Support | AD58: 104802.63 | AE58: Above 100k | AF58: 44502 | AG58: 1 | AH58: Permanent | AI58: Hyderabad, India | AJ58: 2.6356164 | AK58: Full time
...

Sheet Q3 Filter
A1: 3 | B1: All female employees with more than $100k salary | D1: FILTER, * | E1: who joined in 2020 or after…
E3: In The below table all female who have > Than 100K Salary | S3: In the below table all the female who have > 100k salary and joining date after 2020
S4: Salary | T4: 100000 | U4: Gender | V4: Female | W4: Start Date | X4: 43831
E5: {=staff[#Headers]} -> Emp ID | F5: First Name | G5: Last Name | H5: Gender | I5: Department | J5: Salary | K5: Salary Bucket | L5: Start Date | M5: FTE | N5: Employee type | O5: Work location | P5: Tenure | Q5: Work Type | S5: {=staff[#Headers]} -> Emp ID | T5: First Name | U5: Last Name | V5: Gender | W5: Department | X5: Salary | Y5: Salary Bucket | Z5: Start Date | AA5: FTE | AB5: Employee type | AC5: Work location | AD5: Tenure | AE5: Work Type
E6: {=_xlfn._xlws.FILTER(staff[],(staff[Salary]>100000)*(staff[Gender] = "Female"))} -> SQ04612 | F6: Mick | G6: Spraberry | H6: Female | I6: Services | J6: 120000 | K6: Above 100k | L6: 43902 | M6: 0.9 | N6: Permanent | O6: Remote | P6: 4.2794521 | Q6: Part time | S6: {=_xlfn._xlws.FILTER(staff[],(staff[Salary]>T4)*(staff[Gender] = V4)*(staff[Start Date]>=X4))} -> SQ04612 | T6: Mick | U6: Spraberry | V6: Female | W6: Services | X6: 120000 | Y6: Above 100k | Z6: 43902 | AA6: 0.9 | AB6: Permanent | AC6: Remote | AD6: 4.2794521 | AE6: Part time
E7: SQ02174 | F7: Sidoney | G7: Yitzhok | H7: Female | I7: Engineering | J7: 118442.54 | K7: Above 100k | L7: 44193 | M7: 1 | N7: Permanent | O7: Auckland, New Zealand | P7: 3.4821918 | Q7: Full time | S7: SQ02174 | T7: Sidoney | U7: Yitzhok | V7: Female | W7: Engineering | X7: 118442.54 | Y7: Above 100k | Z7: 44193 | AA7: 1 | AB7: Permanent | AC7: Auckland, New Zealand | AD7: 3.4821918 | AE7: Full time
E8: VT04093 | F8: Prasanna | G8: Lakshmi | H8: Female | I8: Training | J8: 116767.63 | K8: Above 100k | L8: 43949 | M8: 0.4 | N8: Temporary | O8: Chennai, India | P8: 4.1506849 | Q8: Part time | S8: VT04093 | T8: Prasanna | U8: Lakshmi | V8: Female | W8: Training | X8: 116767.63 | Y8: Above 100k | Z8: 43949 | AA8: 0.4 | AB8: Temporary | AC8: Chennai, India | AD8: 4.1506849 | AE8: Part time
E9: VT04093 | F9: Baruna | G9: Ogale | H9: Female | I9: Training | J9: 116767.63 | K9: Above 100k | L9: 43949 | M9: 0.4 | N9: Temporary | O9: Chennai, India | P9: 4.1506849 | Q9: Part time | S9: VT04093 | T9: Baruna | U9: Ogale | V9: Female | W9: Training | X9: 116767.63 | Y9: Above 100k | Z9: 43949 | AA9: 0.4 | AB9: Temporary | AC9: Chennai, India | AD9: 4.1506849 | AE9: Part time
E10: SQ02624 | F10: Gwenneth | G10: Fealey | H10: Female | I10: Engineering | J10: 114772.32 | K10: Above 100k | L10: 44251 | M10: 1 | N10: Permanent | O10: Columbus, USA | P10: 3.3232877 | Q10: Full time | S10: SQ02624 | T10: Gwenneth | U10: Fealey | V10: Female | W10: Engineering | X10: 114772.32 | Y10: Above 100k | Z10: 44251 | AA10: 1 | AB10: Permanent | AC10: Columbus, USA | AD10: 3.3232877 | AE10: Full time
E11: TN01281 | F11: Cletus | G11: McGarahan | H11: Female | I11: Engineering | J11: 114425.19 | K11: Above 100k | L11: 43857 | M11: 1 | N11: Permanent | O11: Wellington, New Zealand | P11: 4.4027397 | Q11: Full time | S11: TN01281 | T11: Cletus | U11: McGarahan | V11: Female | W11: Engineering | X11: 114425.19 | Y11: Above 100k | Z11: 43857 | AA11: 1 | AB11: Permanent | AC11: Wellington, New Zealand | AD11: 4.4027397 | AE11: Full time
E12: PR00746 | F12: Hogan | G12: Iles | H12: Female | I12: Accounting | J12: 114177.23 | K12: Above 100k | L12: 43908 | M12: 1 | N12: Permanent | O12: Wellington, New Zealand | P12: 4.2630137 | Q12: Full time | S12: PR00746 | T12: Hogan | U12: Iles | V12: Female | W12: Accounting | X12: 114177.23 | Y12: Above 100k | Z12: 43908 | AA12: 1 | AB12: Permanent | AC12: Wellington, New Zealand | AD12: 4.2630137 | AE12: Full time
E13: SQ00498 | F13: Amery | G13: Ofer | H13: Female | I13: Legal | J13: 111049.84 | K13: Above 100k | L13: 44393 | M13: 1 | N13: Permanent | O13: Wellington, New Zealand | P13: 2.9342466 | Q13: Full time | S13: SQ00498 | T13: Amery | U13: Ofer | V13: Female | W13: Legal | X13: 111049.84 | Y13: Above 100k | Z13: 44393 | AA13: 1 | AB13: Permanent | AC13: Wellington, New Zealand | AD13: 2.9342466 | AE13: Full time
E14: VT04681 | F14: Nickolai | G14: Artin | H14: Female | I14: Product Management | J14: 110906.35 | K14: Above 100k | L14: 43434 | M14: 1 | N14: Temporary | O14: Wellington, New Zealand | P14: 5.5616438 | Q14: Full time | S14: TN00579 | T14: Rafaelita | U14: Blaksland | V14: Female | W14: Services | X14: 109163.39 | Y14: Above 100k | Z14: 44019 | AA14: 0.8 | AB14: Permanent | AC14: Seattle, USA | AD14: 3.9589041 | AE14: Part time
E15: TN00579 | F15: Rafaelita | G15: Blaksland | H15: Female | I15: Services | J15: 109163.39 | K15: Above 100k | L15: 44019 | M15: 0.8 | N15: Permanent | O15: Seattle, USA | P15: 3.9589041 | Q15: Part time | S15: PR02208 | T15: Gowri | U15: Sankar | V15: Female | W15: Training | X15: 102934.09 | Y15: Above 100k | Z15: 44315 | AA15: 1 | AB15: Permanent | AC15: Hyderabad, India | AD15: 3.1479452 | AE15: Full time
E16: VT04552 | F16: Theresita | G16: Chasmer | H16: Female | I16: Product Management | J16: 106665.67 | K16: Above 100k | L16: 43311 | M16: 1 | N16: Temporary | O16: Columbus, USA | P16: 5.8986301 | Q16: Full time | S16: SQ03491 | T16: Freda | U16: Legan | V16: Female | W16: Sales | X16: 102129.37 | Y16: Above 100k | Z16: 44396 | AA16: 1 | AB16: Permanent | AC16: Columbus, USA | AD16: 2.9260274 | AE16: Full time
E17: SQ02703 | F17: Deepit | G17: Ranjana | H17: Female | I17: Marketing | J17: 104903.79 | K17: Above 100k | L17: 43649 | M17: 1 | N17: Permanent | O17: Chennai, India | P17: 4.9726027 | Q17: Full time | S17: SQ03387 | T17: Robinia | U17: Scholling | V17: Female | W17: Human Resources | X17: 100731.95 | Y17: Above 100k | Z17: 43936 | AA17: 1 | AB17: Permanent | AC17: Auckland, New Zealand | AD17: 4.1863014 | AE17: Full time
E18: TN04740 | F18: Tristam | G18: Cuming | H18: Female | I18: Support | J18: 104038.9 | K18: Above 100k | L18: 43815 | M18: 1 | N18: Fixed Term | O18: Remote | P18: 4.5178082 | Q18: Full time | S18: TN04246 | T18: Shaylyn | U18: Ransbury | V18: Female | W18: Support | X18: 100371.31 | Y18: Above 100k | Z18: 44067 | AA18: 0.8 | AB18: Fixed Term | AC18: Auckland, New Zealand | AD18: 3.8273973 | AE18: Part time
E19: PR02208 | F19: Gowri | G19: Sankar | H19: Female | I19: Training | J19: 102934.09 | K19: Above 100k | L19: 44315 | M19: 1 | N19: Permanent | O19: Hyderabad, India | P19: 3.1479452 | Q19: Full time
E20: SQ03491 | F20: Freda | G20: Legan | H20: Female | I20: Sales | J20: 102129.37 | K20: Above 100k | L20: 44396 | M20: 1 | N20: Permanent | O20: Columbus, USA | P20: 2.9260274 | Q20: Full time
E21: VT01684 | F21: Audry | G21: Yu | H21: Female | I21: Training | J21: 101187.36 | K21: Above 100k | L21: 43258 | M21: 1 | N21: Fixed Term | O21: Columbus, USA | P21: 6.0438356 | Q21: Full time
E22: SQ03387 | F22: Robinia | G22: Scholling | H22: Female | I22: Human Resources | J22: 100731.95 | K22: Above 100k | L22: 43936 | M22: 1 | N22: Permanent | O22: Auckland, New Zealand | P22: 4.1863014 | Q22: Full time
E23: TN04246 | F23: Shaylyn | G23: Ransbury | H23: Female | I23: Support | J23: 100371.31 | K23: Above 100k | L23: 44067 | M23: 0.8 | N23: Fixed Term | O23: Auckland, New Zealand | P23: 3.8273973 | Q23: Part time
D32: Only Female Employee Such as greater than 100k salary but we have only req. cloumn - Emp Id to Salary and do not use CHOOSECOLM func.
E35: Salary | F35: 100000 | G35: Gender | H35: Female
D36: {=staff[[#Headers],[Emp ID]:[Salary]]} -> Emp ID | E36: First Name | F36: Last Name | G36: Gender | H36: Department | I36: Salary
D37: {=_xlfn._xlws.FILTER(staff[[Emp ID]:[Salary]],(staff[Salary]>F35)*(staff[Gender] = H35))} -> SQ04612 | E37: Mick | F37: Spraberry | G37: Female | H37: Services | I37: 120000
D38: SQ02174 | E38: Sidoney | F38: Yitzhok | G38: Female | H38: Engineering | I38: 118442.54
D39: VT04093 | E39: Prasanna | F39: Lakshmi | G39: Female | H39: Training | I39: 116767.63
D40: VT04093 | E40: Baruna | F40: Ogale | G40: Female | H40: Training | I40: 116767.63
D41: SQ02624 | E41: Gwenneth | F41: Fealey | G41: Female | H41: Engineering | I41: 114772.32
D42: TN01281 | E42: Cletus | F42: McGarahan | G42: Female | H42: Engineering | I42: 114425.19
D43: PR00746 | E43: Hogan | F43: Iles | G43: Female | H43: Accounting | I43: 114177.23
D44: SQ00498 | E44: Amery | F44: Ofer | G44: Female | H44: Legal | I44: 111049.84
D45: VT04681 | E45: Nickolai | F45: Artin | G45: Female | H45: Product Management | I45: 110906.35
D46: TN00579 | E46: Rafaelita | F46: Blaksland | G46: Female | H46: Services | I46: 109163.39
D47: VT04552 | E47: Theresita | F47: Chasmer | G47: Female | H47: Product Management | I47: 106665.67
D48: SQ02703 | E48: Deepit | F48: Ranjana | G48: Female | H48: Marketing | I48: 104903.79
D49: TN04740 | E49: Tristam | F49: Cuming | G49: Female | H49: Support | I49: 104038.9
... D54: TN04246 | E54: Shaylyn | F54: Ransbury | G54: Female | H54: Support | I54: 100371.31

Sheet Q4 Min, Max, Sort+Take
A2: Lowest, Highest and top 5 salary values
E6: using minifs form
C7: All Emps | D7: Male | E7: Male | F7: Female | G7: Female | O7: 1 | P7: 2 | Q7: 3 | R7: 4 | S7: 5 | T7: 6 | U7: 7 | V7: 8 | W7: 9 | X7: 10 | Y7: 11 | Z7: 12 | AA7: 13
B8: Lowest Salary | C8: =MIN(staff[Salary]) -> 28160.79 | D8: {=MIN(_xlfn._xlws.FILTER(staff[Salary],(staff[Gender] = D7)))} -> 28160.79 | E8: =_xlfn.MINIFS(staff[Salary],staff[Gender],E$7) -> 28160.79 | F8: {=MIN(_xlfn._xlws.FILTER(staff[Salary],(staff[Gender] = F7)))} -> 28305.08 | G8: =_xlfn.MINIFS(staff[Salary],staff[Gender],G$7) -> 28305.08 | I8: {=_xlfn.SEQUENCE(10)} -> 1 | O8: {=staff[#Headers]} -> Emp ID | P8: First Name | Q8: Last Name | R8: Gender | S8: Department | T8: Salary | U8: Salary Bucket | V8: Start Date | W8: FTE | X8: Employee type | Y8: Work location | Z8: Tenure | AA8: Work Type
B9: Highest Salary | C9: =MAX(staff[Salary]) -> 120000 | D9: {=MAX(_xlfn._xlws.FILTER(staff[Salary],staff[Gender]=D7))} -> 120000 | E9: =_xlfn.MAXIFS(staff[Salary],staff[Gender],E$7) -> 120000 | F9: {=MAX(_xlfn._xlws.FILTER(staff[Salary],staff[Gender]=F7))} -> 120000 | G9: =_xlfn.MAXIFS(staff[Salary],staff[Gender],G$7) -> 120000 | I9: 2 | O9: {=staff[]} -> PR00147 | P9: Minerva | Q9: Ricardot | R9: Male | S9: Engineering | T9: 120000 | U9: Above 100k | V9: 43416 | W9: 1 | X9: Permanent | Y9: Remote | Z9: 5.6109589 | AA9: Full time
B10: Top 10 Salaries | C10: =LARGE(staff[Salary],I8) -> 120000 | D10: {=LARGE(_xlfn._xlws.FILTER(staff[Salary],staff[Gender]=$D$7),I8)} -> 120000 | F10: {=LARGE(_xlfn._xlws.FILTER(staff[Salary],staff[Gender]=$F$7),I8)} -> 120000 | I10: 3 | O10: SQ04612 | P10: Mick | Q10: Spraberry | R10: Female | S10: Services | T10: 120000 | U10: Above 100k | V10: 43902 | W10: 0.9 | X10: Permanent | Y10: Remote | Z10: 4.2794521 | AA10: Part time
C11: =LARGE(staff[Salary],I9) -> 120000 | D11: {=LARGE(_xlfn._xlws.FILTER(staff[Salary],staff[Gender]=$D$7),I9)} -> 119022.49 | F11: {=LARGE(_xlfn._xlws.FILTER(staff[Salary],staff[Gender]=$F$7),I9)} -> 118442.54 | I11: 4 | O11: PR03886 | P11: Edd | Q11: MacKnockiter | R11: Male | S11: Accounting | T11: 119022.49 | U11: Above 100k | V11: 44431 | W11: 1 | X11: Permanent | Y11: Auckland, New Zealand | Z11: 2.830137 | AA11: Full time
C12: =LARGE(staff[Salary],I10) -> 119022.49 | D12: {=LARGE(_xlfn._xlws.FILTER(staff[Salary],staff[Gender]=$D$7),I10)} -> 118976.16 | F12: {=LARGE(_xlfn._xlws.FILTER(staff[Salary],staff[Gender]=$F$7),I10)} -> 116767.63 | I12: 5 | O12: SQ00144 | P12: Collen | Q12: Dunbleton | R12: Male | S12: Engineering | T12: 118976.16 | U12: Above 100k | V12: 44120 | W12: 1 | X12: Permanent | Y12: Wellington, New Zealand | Z12: 3.6821918 | AA12: Full time
C13: =LARGE(staff[Salary],I11) -> 118976.16 | D13: {=LARGE(_xlfn._xlws.FILTER(staff[Salary],staff[Gender]=$D$7),I11)} -> 115191.38 | F13: {=LARGE(_xlfn._xlws.FILTER(staff[Salary],staff[Gender]=$F$7),I11)} -> 116767.63 | I13: 6 | O13: SQ02174 | P13: Sidoney | Q13: Yitzhok | R13: Female | S13: Engineering | T13: 118442.54 | U13: Above 100k | V13: 44193 | W13: 1 | X13: Permanent | Y13: Auckland, New Zealand | Z13: 3.4821918 | AA13: Full time | AE13: Gender | AF13: Female | AG13: No.s | AH13: 8
C14: =LARGE(staff[Salary],I12) -> 118442.54 | D14: {=LARGE(_xlfn._xlws.FILTER(staff[Salary],staff[Gender]=$D$7),I12)} -> 114691.03 | F14: {=LARGE(_xlfn._xlws.FILTER(staff[Salary],staff[Gender]=$F$7),I12)} -> 114772.32 | I14: 7 | O14: VT04093 | P14: Prasanna | Q14: Lakshmi | R14: Female | S14: Training | T14: 116767.63 | U14: Above 100k | V14: 43949 | W14: 0.4 | X14: Temporary | Y14: Chennai, India | Z14: 4.1506849 | AA14: Part time
C15: =LARGE(staff[Salary],I13) -> 116767.63 | D15: {=LARGE(_xlfn._xlws.FILTER(staff[Salary],staff[Gender]=$D$7),I13)} -> 114465.93 | F15: {=LARGE(_xlfn._xlws.FILTER(staff[Salary],staff[Gender]=$F$7),I13)} -> 114425.19 | I15: 8 | O15: VT04093 | P15: Baruna | Q15: Ogale | R15: Female | S15: Training | T15: 116767.63 | U15: Above 100k | V15: 43949 | W15: 0.4 | X15: Temporary | Y15: Chennai, India | Z15: 4.1506849 | AA15: Part time | AF15: {=_xlfn.TAKE(_xlfn._xlws.SORT(_xlfn._xlws.FILTER(T9:T268,R9:R268=AF13),,-1),AH13)} -> 120000
C16: =LARGE(staff[Salary],I14) -> 116767.63 | D16: {=LARGE(_xlfn._xlws.FILTER(staff[Salary],staff[Gender]=$D$7),I14)} -> 113747.56 | F16: {=LARGE(_xlfn._xlws.FILTER(staff[Salary],staff[Gender]=$F$7),I14)} -> 114177.23 | I16: 9 | O16: PR02010 | P16: Prerana | Q16: Nishita | R16: Male | S16: Product Management | T16: 115191.38 | U16: Above 100k | V16: 44004 | W16: 1 | X16: Permanent | Y16: Hyderabad, India | Z16: 4 | AA16: Full time | AF16: 118442.54
C17: =LARGE(staff[Salary],I15) -> 115191.38 | D17: {=LARGE(_xlfn._xlws.FILTER(staff[Salary],staff[Gender]=$D$7),I15)} -> 113747.56 | F17: {=LARGE(_xlfn._xlws.FILTER(staff[Salary],staff[Gender]=$F$7),I15)} -> 111049.84 | I17: 10 | O17: SQ02624 | P17: Gwenneth | Q17: Fealey | R17: Female | S17: Engineering | T17: 114772.32 | U17: Above 100k | V17: 44251 | W17: 1 | X17: Permanent | Y17: Columbus, USA | Z17: 3.3232877 | AA17: Full time | AF17: 116767.63
C18: =LARGE(staff[Salary],I16) -> 114772.32 | D18: {=LARGE(_xlfn._xlws.FILTER(staff[Salary],staff[Gender]=$D$7),I16)} -> 113616.23 | F18: {=LARGE(_xlfn._xlws.FILTER(staff[Salary],staff[Gender]=$F$7),I16)} -> 110906.35 | O18: VT02801 | P18: Shellysheldon | Q18: Mahady | R18: Male | S18: Training | T18: 114691.03 | U18: Above 100k | V18: 44039 | W18: 1 | X18: Temporary | Y18: Wellington, New Zealand | Z18: 3.9041096 | AA18: Full time | AF18: 116767.63
C19: =LARGE(staff[Salary],I17) -> 114691.03 | D19: {=LARGE(_xlfn._xlws.FILTER(staff[Salary],staff[Gender]=$D$7),I17)} -> 112778.28 | F19: {=LARGE(_xlfn._xlws.FILTER(staff[Salary],staff[Gender]=$F$7),I17)} -> 109163.39 | O19: VT02491 | P19: Alexis | Q19: Gotfrey | R19: Male | S19: Engineering | T19: 114465.93 | U19: Above 100k | V19: 43291 | W19: 1 | X19: Temporary | Y19: Wellington, New Zealand | Z19: 5.9534247 | AA19: Full time | AF19: 114772.32
O20: TN01281 | P20: Cletus | Q20: McGarahan | R20: Female | S20: Engineering | T20: 114425.19 | U20: Above 100k | V20: 43857 | W20: 1 | X20: Permanent | Y20: Wellington, New Zealand | Z20: 4.4027397 | AA20: Full time | AF20: 114425.19
O21: PR00746 | P21: Hogan | Q21: Iles | R21: Female | S21: Accounting | T21: 114177.23 | U21: Above 100k | V21: 43908 | W21: 1 | X21: Permanent | Y21: Wellington, New Zealand | Z21: 4.2630137 | AA21: Full time | AF21: 114177.23
F22: Female | G22: Male | O22: VT03421 | P22: Alic | Q22: Bagg | R22: Male | S22: Legal | T22: 113747.56 | U22: Above 100k | V22: 44270 | W22: 0.7 | X22: Temporary | Y22: Columbus, USA | Z22: 3.2712329 | AA22: Part time | AF22: 111049.84
B23: Top 5 Salaries | C23: {=_xlfn.TAKE(_xlfn._xlws.SORT(staff[Salary],,-1),J23)} -> 120000 | D23: {=_xlfn.TAKE(_xlfn._xlws.SORT(_xlfn._xlws.FILTER(staff[Salary],staff[Gender]=G22),,-1),J23)} -> 120000 | F23: {=_xlfn.TAKE(_xlfn._xlws.SORT(_xlfn._xlws.FILTER(staff[Salary],staff[Gender]=F22),,-1),J23)} -> 120000 | J23: 10 | O23: VT03421 | P23: Alic | Q23: Bagg | R23: Male | S23: Legal | T23: 113747.56 | U23: Above 100k | V23: 44270 | W23: 0.7 | X23: Temporary | Y23: Columbus, USA | Z23: 3.2712329 | AA23: Part time
B24: With Sort + Take | C24: 120000 | D24: 119022.49 | F24: 118442.54 | O24: SQ01620 | P24: Westbrook | Q24: Brandino | R24: Male | S24: Legal | T24: 113616.23 | U24: Above 100k | V24: 43255 | W24: 1 | X24: Permanent | Y24: Remote | Z24: 6.0520548 | AA24: Full time
C25: 119022.49 | D25: 118976.16 | F25: 116767.63 | O25: VT01893 | P25: Lindy | Q25: Guillet | R25: Male | S25: Training | T25: 112778.28 | U25: Above 100k | V25: 43250 | W25: 1 | X25: Fixed Term | Y25: Remote | Z25: 6.0657534 | AA25: Full time
C26: 118976.16 | D26: 115191.38 | F26: 116767.63 | O26: VT01893 | P26: Lindy | Q26: Guillet | R26: Male | S26: Training | T26: 112778.28 | U26: Above 100k | V26: 43250 | W26: 1 | X26: Fixed Term | Y26: Remote | Z26: 6.0657534 | AA26: Full time | AE26: Gender | AF26: Male | AG26: No. Of Emp | AH26: 10
C27: 118442.54 | D27: 114691.03 | F27: 114772.32 | O27: PR01159 | P27: Mollie | Q27: Hanway | R27: Male | S27: Engineering | T27: 112645.99 | U27: Above 100k | V27: 43759 | W27: 0.6 | X27: Permanent | Y27: Seattle, USA | Z27: 4.6712329 | AA27: Part time
C28: 116767.63 | D28: 114465.93 | F28: 114425.19 | O28: VT04028 | P28: Michale | Q28: Rolf | R28: Male | S28: Services | T28: 111815.49 | U28: Above 100k | V28: 43895 | W28: 0.7 | X28: Temporary | Y28: Remote | Z28: 4.2986301 | AA28: Part time | AD28: {=_xlfn.CHOOSECOLS(_xlfn.TAKE(_xlfn._xlws.SORT(_xlfn._xlws.FILTER(O9:AA268,R9:R268=AF26),6,-1),AH26),1,2,3,4,6,8)} -> PR00147 | AE28: Minerva | AF28: Ricardot | AG28: Male | AH28: 120000 | AI28: 43416
C29: 116767.63 | D29: 113747.56 | F29: 114177.23 | O29: VT04028 | P29: Michale | Q29: Rolf | R29: Male | S29: Services | T29: 111815.49 | U29: Above 100k | V29: 43895 | W29: 0.7 | X29: Temporary | Y29: Remote | Z29: 4.2986301 | AA29: Part time | AD29: PR03886 | AE29: Edd | AF29: MacKnockiter | AG29: Male | AH29: 119022.49 | AI29: 44431
C30: 115191.38 | D30: 113747.56 | F30: 111049.84 | O30: SQ04603 | P30: Natalee | Q30: Craiker | R30: Male | S30: Product Management | T30: 111229.47 | U30: Above 100k | V30: 43402 | W30: 1 | X30: Permanent | Y30: Remote | Z30: 5.6493151 | AA30: Full time | AD30: SQ00144 | AE30: Collen | AF30: Dunbleton | AG30: Male | AH30: 118976.16 | AI30: 44120
C31: 114772.32 | D31: 113616.23 | F31: 110906.35 | O31: SQ00498 | P31: Amery | Q31: Ofer | R31: Female | S31: Legal | T31: 111049.84 | U31: Above 100k | V31: 44393 | W31: 1 | X31: Permanent | Y31: Wellington, New Zealand | Z31: 2.9342466 | AA31: Full time | AD31: PR02010 | AE31: Prerana | AF31: Nishita | AG31: Male | AH31: 115191.38 | AI31: 44004
C32: 114691.03 | D32: 112778.28 | F32: 109163.39 | O32: VT04681 | P32: Nickolai | Q32: Artin | R32: Female | S32: Product Management | T32: 110906.35 | U32: Above 100k | V32: 43434 | W32: 1 | X32: Temporary | Y32: Wellington, New Zealand | Z32: 5.5616438 | AA32: Full time | AD32: VT02801 | AE32: Shellysheldon | AF32: Mahady | AG32: Male | AH32: 114691.03 | AI32: 44039
O33: SQ00022 | P33: Carlin | Q33: Demke | R33: Male | S33: Business Development | T33: 110042.37 | U33: Above 100k | V33: 43914 | W33: 1 | X33: Permanent | Y33: Columbus, USA | Z33: 4.2465753 | AA33: Full time | AD33: VT02491 | AE33: Alexis | AF33: Gotfrey | AG33: Male | AH33: 114465.93 | AI33: 43291
O34: TN00579 | P34: Rafaelita | Q34: Blaksland | R34: Female | S34: Services | T34: 109163.39 | U34: Above 100k | V34: 44019 | W34: 0.8 | X34: Permanent | Y34: Seattle, USA | Z34: 3.9589041 | AA34: Part time | AD34: VT03421 | AE34: Alic | AF34: Bagg | AG34: Male | AH34: 113747.56 | AI34: 44270
O35: SQ03733 | P35: Revkah | Q35: Antonacci | R35: Male | S35: Engineering | T35: 109143.17 | U35: Above 100k | V35: 43945 | W35: 1 | X35: Permanent | Y35: Wellington, New Zealand | Z35: 4.1616438 | AA35: Full time | AD35: VT03421 | AE35: Alic | AF35: Bagg | AG35: Male | AH35: 113747.56 | AI35: 44270
O36: SQ03116 | P36: Syd | Q36: Fearn | R36: Male | S36: Engineering | T36: 108872.77 | U36: Above 100k | V36: 43521 | W36: 1 | X36: Permanent | Y36: Remote | Z36: 5.3232877 | AA36: Full time | AD36: SQ01620 | AE36: Westbrook | AF36: Brandino | AG36: Male | AH36: 113616.23 | AI36: 43255
O37: SQ03476 | P37: Ramalingam | Q37: Kothapeta | R37: Need to check | S37: Accounting | T37: 107107.6 | U37: Above 100k | V37: 43325 | W37: 0.9 | X37: Permanent | Y37: Chennai, India | Z37: 5.860274 | AA37: Part time | AD37: VT01893 | AE37: Lindy | AF37: Guillet | AG37: Male | AH37: 112778.28 | AI37: 43250
O38: TN04058 | P38: Subbarao | Q38: Malladi | R38: Male | S38: Product Management | T38: 106775.14 | U38: Above 100k | V38: 43563 | W38: 1 | X38: Fixed Term | Y38: Hyderabad, India | Z38: 5.2082192 | AA38: Full time
O39: TN04058 | P39: Vasu | Q39: Nandin | R39: Male | S39: Product Management | T39: 106775.14 | U39: Above 100k | V39: 43563 | W39: 1 | X39: Fixed Term | Y39: Hyderabad, India | Z39: 5.2082192 | AA39: Full time
O40: VT04552 | P40: Theresita | Q40: Chasmer | R40: Female | S40: Product Management | T40: 106665.67 | U40: Above 100k | V40: 43311 | W40: 1 | X40: Temporary | Y40: Columbus, USA | Z40: 5.8986301 | AA40: Full time
O41: VT04350 | P41: Kulbhushan | Q41: Moorthy | R41: Male | S41: Business Development | T41: 106400.02 | U41: Above 100k | V41: 44021 | W41: 1 | X41: Temporary | Y41: Chennai, India | Z41: 3.9534247 | AA41: Full time
O42: VT04350 | P42: Lalit | Q42: Kothari | R42: Male | S42: Business Development | T42: 106400.02 | U42: Above 100k | V42: 44021 | W42: 1 | X42: Temporary | Y42: Chennai, India | Z42: 3.9534247 | AA42: Full time
O43: SQ02703 | P43: Deepit | Q43: Ranjana | R43: Female | S43: Marketing | T43: 104903.79 | U43: Above 100k | V43: 43649 | W43: 1 | X43: Permanent | Y43: Chennai, India | Z43: 4.9726027 | AA43: Full time
